Workbook

Sheet Raw_Data
A1: Job_ID | B1: Job_Title | C1: Company | D1: Location | E1: Experience | F1: Skill | G1: Industry | H1: Salary_LPA | I1: Job_Type | J1: Posted_Date | K1: Applications | L1: Status
A2: J001 | B2: Software Developer | C2: TechNova | D2: Bengaluru | E2: Fresher | F2: Java | G2: IT | H2: 6.5 | I2: Full Time | J2: 05-Jan-2026 | K2: 245 | L2: Open
A3: J002 | B3: Data Analyst | C3: DataSphere | D3: Hyderabad | E3: 1-2 Years | F3: SQL | G3: Analytics | H3: 7.2 | I3: Full Time | J3: 08-Jan-2026 | K3: 189 | L3: Open
A4: J003 | B4: Python Developer | C4: CodeWorks | D4: Pune | E4: 1-2 Years | F4: Python | G4: IT | H4: 8 | I4: Full Time | J4: 12-Jan-2026 | K4: 210 | L4: Open
A5: J004 | B5: AI Engineer | C5: InnovateAI | D5: Bengaluru | E5: 2-3 Years | F5: AI/ML | G5: AI | H5: 12.5 | I5: Full Time | J5: 18-Jan-2026 | K5: 156 | L5: Open
A6: J005 | B6: Cybersecurity Analyst | C6: SecureNet | D6: Chennai | E6: Fresher | F6: Cybersecurity | G6: Security | H6: 6.8 | I6: Full Time | J6: 22-Jan-2026 | K6: 178 | L6: Closed
A7: J006 | B7: Software Engineer | C7: CloudTech | D7: Hyderabad | E7: 2-3 Years | F7: Python | G7: IT | H7: 9.5 | I7: Full Time | J7: 02-Feb-2026 | K7: 220 | L7: Open
A8: J007 | B8: Data Scientist | C8: AnalyticsPro | D8: Bengaluru | E8: 3-5 Years | F8: Python | G8: Analytics | H8: 14 | I8: Full Time | J8: 07-Feb-2026 | K8: 134 | L8: Open
A9: J008 | B9: Frontend Developer | C9: WebWorks | D9: Pune | E9: Fresher | F9: JavaScript | G9: IT | H9: 5.8 | I9: Full Time | J9: 11-Feb-2026 | K9: 267 | L9: Open
A10: J009 | B10: Backend Developer | C10: TechNova | D10: Chennai | E10: 1-2 Years | F10: Java | G10: IT | H10: 8.2 | I10: Full Time | J10: 16-Feb-2026 | K10: 198 | L10: Open
A11: J010 | B11: Cloud Engineer | C11: CloudTech | D11: Bengaluru | E11: 2-3 Years | F11: AWS | G11: Cloud | H11: 11.5 | I11: Full Time | J11: 24-Feb-2026 | K11: 145 | L11: Open
A12: J011 | B12: Software Developer | C12: InfoSoft | D12: Mysore | E12: Fresher | F12: C++ | G12: IT | H12: 5.5 | I12: Full Time | J12: 03-Mar-2026 | K12: 289 | L12: Open
A13: J012 | B13: Business Analyst | C13: BusinessHub | D13: Mumbai | E13: 1-2 Years | F13: Excel | G13: Analytics | H13: 7.8 | I13: Full Time | J13: 08-Mar-2026 | K13: 176 | L13: Open
... A41: J040 | B41: Business Analyst | C41: BusinessHub | D41: Bengaluru | E41: 1-2 Years | F41: Power BI | G41: Analytics | H41: 8.3 | I41: Full Time | J41: 13-Aug-2026 | K41: 192 | L41: Open
I42: =AVERAGE(H2:H41) -> 9.0275 | K42: =SUM(K2:K41) -> 7979

Sheet PivotTables
A1: Job Title | B1: Number of Jobs | D1: Company | E1: Number of Jobs | G1: Location | H1: Number of Jobs | J1: Status | K1: Count | V1: Location | W1: Open | X1: Closed
A2: Software Developer | B2: =COUNTIF(Raw_Data!B:B,A2) -> 3 | D2: TechNova | E2: =COUNTIF(Raw_Data!C:C,D2) -> 4 | G2: Bengaluru | H2: =COUNTIF(Raw_Data!D:D,G2) -> 12 | J2: Open | K2: 36 | V2: Bengaluru | W2: =COUNTIFS(Raw_Data!D:D,V2,Raw_Data!L:L,"Open") -> 11 | X2: =COUNTIFS(Raw_Data!D:D,V2,Raw_Data!L:L,"Closed") -> 1
A3: Data Analyst | B3: =COUNTIF(Raw_Data!B:B,A3) -> 3 | D3: DataSphere | E3: =COUNTIF(Raw_Data!C:C,D3) -> 4 | G3: Mysore | H3: =COUNTIF(Raw_Data!D:D,G3) -> 2 | J3: Closed | K3: 4 | V3: Mysore | W3: =COUNTIFS(Raw_Data!D:D,V3,Raw_Data!L:L,"Open") -> 2 | X3: =COUNTIFS(Raw_Data!D:D,V3,Raw_Data!L:L,"Closed") -> 0
A4: Python Developer | B4: =COUNTIF(Raw_Data!B:B,A4) -> 2 | D4: CodeWorks | E4: =COUNTIF(Raw_Data!C:C,D4) -> 3 | G4: Mumbai | H4: =COUNTIF(Raw_Data!D:D,G4) -> 4 | V4: Mumbai | W4: =COUNTIFS(Raw_Data!D:D,V4,Raw_Data!L:L,"Open") -> 4 | X4: =COUNTIFS(Raw_Data!D:D,V4,Raw_Data!L:L,"Closed") -> 0
A5: AI Engineer | B5: =COUNTIF(Raw_Data!B:B,A5) -> 2 | D5: InnovateAI | E5: =COUNTIF(Raw_Data!C:C,D5) -> 5 | G5: Pune | H5: =COUNTIF(Raw_Data!D:D,G5) -> 7 | V5: Pune | W5: =COUNTIFS(Raw_Data!D:D,V5,Raw_Data!L:L,"Open") -> 7 | X5: =COUNTIFS(Raw_Data!D:D,V5,Raw_Data!L:L,"Closed") -> 0
A6: Cybersecurity Analyst | B6: =COUNTIF(Raw_Data!B:B,A6) -> 3 | D6: SecureNet | E6: =COUNTIF(Raw_Data!C:C,D6) -> 4 | G6: Hyderabad | H6: =COUNTIF(Raw_Data!D:D,G6) -> 8 | V6: Hyderabad | W6: =COUNTIFS(Raw_Data!D:D,V6,Raw_Data!L:L,"Open") -> 7 | X6: =COUNTIFS(Raw_Data!D:D,V6,Raw_Data!L:L,"Closed") -> 1
A7: Software Engineer | B7: =COUNTIF(Raw_Data!B:B,A7) -> 2 | D7: CloudTech | E7: =COUNTIF(Raw_Data!C:C,D7) -> 6 | G7: Chennai | H7: =COUNTIF(Raw_Data!D:D,G7) -> 7 | V7: Chennai | W7: =COUNTIFS(Raw_Data!D:D,V7,Raw_Data!L:L,"Open") -> 5 | X7: =COUNTIFS(Raw_Data!D:D,V7,Raw_Data!L:L,"Closed") -> 2
A8: Data Scientist | B8: =COUNTIF(Raw_Data!B:B,A8) -> 3 | D8: InfoSoft | E8: =COUNTIF(Raw_Data!C:C,D8) -> 3
A9: Frontend Developer | B9: =COUNTIF(Raw_Data!B:B,A9) -> 3 | D9: BusinessHub | E9: =COUNTIF(Raw_Data!C:C,D9) -> 3
A10: Backend Developer | B10: =COUNTIF(Raw_Data!B:B,A10) -> 2 | D10: WebWorks | E10: =COUNTIF(Raw_Data!C:C,D10) -> 3
A11: Cloud Engineer | B11: =COUNTIF(Raw_Data!B:B,A11) -> 3 | D11: AnalyticsPro | E11: =COUNTIF(Raw_Data!C:C,D11) -> 3
A13: Location | B13: Average Salary (LPA)
A14: Bengaluru | B14: =AVERAGEIF(Raw_Data!$D$2:$D$41,A14,Raw_Data!$H$2:$H$41) -> 10.266667
A15: Mysore | B15: =AVERAGEIF(Raw_Data!$D$2:$D$41,A15,Raw_Data!$H$2:$H$41) -> 6.7
A16: Pune | B16: =AVERAGEIF(Raw_Data!$D$2:$D$41,A16,Raw_Data!$H$2:$H$41) -> 8.5714286
A17: Hyderabad | B17: =AVERAGEIF(Raw_Data!$D$2:$D$41,A17,Raw_Data!$H$2:$H$41) -> 8.85
A18: Chennai | B18: =AVERAGEIF(Raw_Data!$D$2:$D$41,A18,Raw_Data!$H$2:$H$41) -> 7.6285714

Sheet Job Dashboard 
A2: Job Scope -IT Job Market Analytics 💼
Q11: 📌 Job Market Snapshot
Q12: Total Jobs | R12: 40
Q13: Open Jobs | R13: 36
Q14: Closed Jobs | R14: 4
Q15: Top Location | R15: Bengaluru
Q16: Average Salary (LPA) | R16: 9.03
Q17: Total Applications | R17: 7979
Q21: Applications by Location🌏
Q22: Bengaluru | R22: 2172
Q23: Mysore | R23: 510
Q24: Mumbai | R24: 665
Q25: Pune | R25: 1426
Q26: Hyderabad | R26: 1704
Q27: Chennai | R27: 1459
Q33: 💻 Jobs by Skill
Q34: Skill | R34: Number of Jobs
Q35: Java | R35: 5
Q36: SQL | R36: 3
Q37: Python | R37: 6
Q38: AI/ML | R38: 3
Q39: Cybersecurity | R39: 3
Q40: JavaScript | R40: 3
Q41: AWS | R41: 3
Q42: C++ | R42: 2
Q43: Excel | R43: 2
Q44: Machine Learning | R44: 2
Q45: Figma | R45: 2
Q46: Docker | R46: 2
... Q49: C | R49: 1
Q54: Dashboard Summary📊
Q55: Total Jobs | R55: 40
Q56: Open Jobs | R56: 36
Q57: Closed Jobs | R57: 4
Q58: Open % | R58: 0.9
Q59: Closed % | R59: 0.1
B79: 📈 Key Insights | C79: 💡 Market Highlights
B81: 📍 Bengaluru has the highest number of jobs | C81: 🏙️ Bengaluru leads with 12 jobs
B82: 💼 90% of jobs are currently open | C82: 📊 90% of jobs are open
B83: 💰 Average salary is 9.03 LPA | C83: 💰 Average salary: 9.03 LPA
...
